[2024-05-15T03:17:25.574+0800] {local_task_job_runner.py:120} INFO - ::group::Pre task execution logs
[2024-05-15T03:17:25.600+0800] {taskinstance.py:2076} INFO - Dependencies all met for dep_context=non-requeueable deps ti=<TaskInstance: census_data_pipeline.process_data manual__2024-05-14T19:17:19.723969+00:00 [queued]>
[2024-05-15T03:17:25.604+0800] {taskinstance.py:2076} INFO - Dependencies all met for dep_context=requeueable deps ti=<TaskInstance: census_data_pipeline.process_data manual__2024-05-14T19:17:19.723969+00:00 [queued]>
[2024-05-15T03:17:25.604+0800] {taskinstance.py:2306} INFO - Starting attempt 1 of 2
[2024-05-15T03:17:25.615+0800] {taskinstance.py:2330} INFO - Executing <Task(PythonOperator): process_data> on 2024-05-14 19:17:19.723969+00:00
[2024-05-15T03:17:25.618+0800] {standard_task_runner.py:63} INFO - Started process 77280 to run task
[2024-05-15T03:17:25.620+0800] {standard_task_runner.py:90} INFO - Running: ['airflow', 'tasks', 'run', 'census_data_pipeline', 'process_data', 'manual__2024-05-14T19:17:19.723969+00:00', '--job-id', '9', '--raw', '--subdir', 'DAGS_FOLDER/my_dag.py', '--cfg-path', '/tmp/tmpovpio2wj']
[2024-05-15T03:17:25.621+0800] {standard_task_runner.py:91} INFO - Job 9: Subtask process_data
[2024-05-15T03:17:25.648+0800] {task_command.py:426} INFO - Running <TaskInstance: census_data_pipeline.process_data manual__2024-05-14T19:17:19.723969+00:00 [running]> on host jithish-HP-ZBook-17-G5
[2024-05-15T03:17:25.689+0800] {taskinstance.py:2648} INFO - Exporting env vars: AIRFLOW_CTX_DAG_EMAIL='example@example.com' AIRFLOW_CTX_DAG_OWNER='airflow' AIRFLOW_CTX_DAG_ID='census_data_pipeline' AIRFLOW_CTX_TASK_ID='process_data' AIRFLOW_CTX_EXECUTION_DATE='2024-05-14T19:17:19.723969+00:00' AIRFLOW_CTX_TRY_NUMBER='1' AIRFLOW_CTX_DAG_RUN_ID='manual__2024-05-14T19:17:19.723969+00:00'
[2024-05-15T03:17:25.690+0800] {taskinstance.py:430} INFO - ::endgroup::
[2024-05-15T03:17:25.699+0800] {logging_mixin.py:188} WARNING - /home/jithish/Documents/dag-dag-dag/airflow/dags/my_dag.py:36 FutureWarning: DataFrame.fillna with 'method' is deprecated and will raise in a future version. Use obj.ffill() or obj.bfill() instead.
[2024-05-15T03:17:25.700+0800] {taskinstance.py:441} INFO - ::group::Post task execution logs
[2024-05-15T03:17:25.701+0800] {taskinstance.py:2905} ERROR - Task failed with exception
Traceback (most recent call last):
  File "/home/jithish/Documents/dag-dag-dag/.venv/lib/python3.10/site-packages/pandas/core/indexes/base.py", line 3805, in get_loc
    return self._engine.get_loc(casted_key)
  File "index.pyx", line 167, in pandas._libs.index.IndexEngine.get_loc
  File "index.pyx", line 196, in pandas._libs.index.IndexEngine.get_loc
  File "pandas/_libs/hashtable_class_helper.pxi", line 7081, in pandas._libs.hashtable.PyObjectHashTable.get_item
  File "pandas/_libs/hashtable_class_helper.pxi", line 7089, in pandas._libs.hashtable.PyObjectHashTable.get_item
KeyError: 'Population'

The above exception was the direct cause of the following exception:

Traceback (most recent call last):
  File "/home/jithish/Documents/dag-dag-dag/.venv/lib/python3.10/site-packages/airflow/models/taskinstance.py", line 465, in _execute_task
    result = _execute_callable(context=context, **execute_callable_kwargs)
  File "/home/jithish/Documents/dag-dag-dag/.venv/lib/python3.10/site-packages/airflow/models/taskinstance.py", line 432, in _execute_callable
    return execute_callable(context=context, **execute_callable_kwargs)
  File "/home/jithish/Documents/dag-dag-dag/.venv/lib/python3.10/site-packages/airflow/models/baseoperator.py", line 400, in wrapper
    return func(self, *args, **kwargs)
  File "/home/jithish/Documents/dag-dag-dag/.venv/lib/python3.10/site-packages/airflow/operators/python.py", line 235, in execute
    return_value = self.execute_callable()
  File "/home/jithish/Documents/dag-dag-dag/.venv/lib/python3.10/site-packages/airflow/operators/python.py", line 252, in execute_callable
    return self.python_callable(*self.op_args, **self.op_kwargs)
  File "/home/jithish/Documents/dag-dag-dag/airflow/dags/my_dag.py", line 38, in clean_and_process_data
    filtered_df = df[df['Population'] > 100000]
  File "/home/jithish/Documents/dag-dag-dag/.venv/lib/python3.10/site-packages/pandas/core/frame.py", line 4102, in __getitem__
    indexer = self.columns.get_loc(key)
  File "/home/jithish/Documents/dag-dag-dag/.venv/lib/python3.10/site-packages/pandas/core/indexes/base.py", line 3812, in get_loc
    raise KeyError(key) from err
KeyError: 'Population'
[2024-05-15T03:17:25.705+0800] {taskinstance.py:1206} INFO - Marking task as UP_FOR_RETRY. dag_id=census_data_pipeline, task_id=process_data, run_id=manual__2024-05-14T19:17:19.723969+00:00, execution_date=20240514T191719, start_date=20240514T191725, end_date=20240514T191725
[2024-05-15T03:17:25.715+0800] {standard_task_runner.py:110} ERROR - Failed to execute job 9 for task process_data ('Population'; 77280)
[2024-05-15T03:17:25.752+0800] {local_task_job_runner.py:240} INFO - Task exited with return code 1
[2024-05-15T03:17:25.792+0800] {taskinstance.py:3498} INFO - 0 downstream tasks scheduled from follow-on schedule check
[2024-05-15T03:17:25.793+0800] {local_task_job_runner.py:222} INFO - ::endgroup::
