[2024-05-15T04:08:43.693+0800] {local_task_job_runner.py:120} INFO - ::group::Pre task execution logs
[2024-05-15T04:08:43.716+0800] {taskinstance.py:2076} INFO - Dependencies all met for dep_context=non-requeueable deps ti=<TaskInstance: census_data_pipeline.store_data manual__2024-05-14T20:03:27.189773+00:00 [queued]>
[2024-05-15T04:08:43.720+0800] {taskinstance.py:2076} INFO - Dependencies all met for dep_context=requeueable deps ti=<TaskInstance: census_data_pipeline.store_data manual__2024-05-14T20:03:27.189773+00:00 [queued]>
[2024-05-15T04:08:43.720+0800] {taskinstance.py:2306} INFO - Starting attempt 1 of 2
[2024-05-15T04:08:43.731+0800] {taskinstance.py:2330} INFO - Executing <Task(PythonOperator): store_data> on 2024-05-14 20:03:27.189773+00:00
[2024-05-15T04:08:43.734+0800] {standard_task_runner.py:63} INFO - Started process 114434 to run task
[2024-05-15T04:08:43.737+0800] {standard_task_runner.py:90} INFO - Running: ['airflow', 'tasks', 'run', 'census_data_pipeline', 'store_data', 'manual__2024-05-14T20:03:27.189773+00:00', '--job-id', '20', '--raw', '--subdir', 'DAGS_FOLDER/my_dag.py', '--cfg-path', '/tmp/tmpbki63h1m']
[2024-05-15T04:08:43.740+0800] {standard_task_runner.py:91} INFO - Job 20: Subtask store_data
[2024-05-15T04:08:43.767+0800] {task_command.py:426} INFO - Running <TaskInstance: census_data_pipeline.store_data manual__2024-05-14T20:03:27.189773+00:00 [running]> on host jithish-HP-ZBook-17-G5
[2024-05-15T04:08:43.819+0800] {taskinstance.py:2648} INFO - Exporting env vars: AIRFLOW_CTX_DAG_EMAIL='example@example.com' AIRFLOW_CTX_DAG_OWNER='airflow' AIRFLOW_CTX_DAG_ID='census_data_pipeline' AIRFLOW_CTX_TASK_ID='store_data' AIRFLOW_CTX_EXECUTION_DATE='2024-05-14T20:03:27.189773+00:00' AIRFLOW_CTX_TRY_NUMBER='1' AIRFLOW_CTX_DAG_RUN_ID='manual__2024-05-14T20:03:27.189773+00:00'
[2024-05-15T04:08:43.820+0800] {taskinstance.py:430} INFO - ::endgroup::
[2024-05-15T04:08:43.832+0800] {logging_mixin.py:188} WARNING - /home/jithish/Documents/dag-dag-dag/airflow/dags/my_dag.py:49 UserWarning: pandas only supports SQLAlchemy connectable (engine/connection) or database string URI or sqlite3 DBAPI2 connection. Other DBAPI2 objects are not tested. Please consider using SQLAlchemy.
[2024-05-15T04:08:43.833+0800] {taskinstance.py:441} INFO - ::group::Post task execution logs
[2024-05-15T04:08:43.834+0800] {taskinstance.py:2905} ERROR - Task failed with exception
Traceback (most recent call last):
  File "/home/jithish/Documents/dag-dag-dag/.venv/lib/python3.10/site-packages/airflow/models/taskinstance.py", line 465, in _execute_task
    result = _execute_callable(context=context, **execute_callable_kwargs)
  File "/home/jithish/Documents/dag-dag-dag/.venv/lib/python3.10/site-packages/airflow/models/taskinstance.py", line 432, in _execute_callable
    return execute_callable(context=context, **execute_callable_kwargs)
  File "/home/jithish/Documents/dag-dag-dag/.venv/lib/python3.10/site-packages/airflow/models/baseoperator.py", line 400, in wrapper
    return func(self, *args, **kwargs)
  File "/home/jithish/Documents/dag-dag-dag/.venv/lib/python3.10/site-packages/airflow/operators/python.py", line 235, in execute
    return_value = self.execute_callable()
  File "/home/jithish/Documents/dag-dag-dag/.venv/lib/python3.10/site-packages/airflow/operators/python.py", line 252, in execute_callable
    return self.python_callable(*self.op_args, **self.op_kwargs)
  File "/home/jithish/Documents/dag-dag-dag/airflow/dags/my_dag.py", line 49, in store_data
    df.to_sql('census_data', con=engine, if_exists='replace', index=False)
  File "/home/jithish/Documents/dag-dag-dag/.venv/lib/python3.10/site-packages/pandas/util/_decorators.py", line 333, in wrapper
    return func(*args, **kwargs)
  File "/home/jithish/Documents/dag-dag-dag/.venv/lib/python3.10/site-packages/pandas/core/generic.py", line 3087, in to_sql
    return sql.to_sql(
  File "/home/jithish/Documents/dag-dag-dag/.venv/lib/python3.10/site-packages/pandas/io/sql.py", line 842, in to_sql
    return pandas_sql.to_sql(
  File "/home/jithish/Documents/dag-dag-dag/.venv/lib/python3.10/site-packages/pandas/io/sql.py", line 2850, in to_sql
    table.create()
  File "/home/jithish/Documents/dag-dag-dag/.venv/lib/python3.10/site-packages/pandas/io/sql.py", line 984, in create
    if self.exists():
  File "/home/jithish/Documents/dag-dag-dag/.venv/lib/python3.10/site-packages/pandas/io/sql.py", line 970, in exists
    return self.pd_sql.has_table(self.name, self.schema)
  File "/home/jithish/Documents/dag-dag-dag/.venv/lib/python3.10/site-packages/pandas/io/sql.py", line 2865, in has_table
    return len(self.execute(query, [name]).fetchall()) > 0
  File "/home/jithish/Documents/dag-dag-dag/.venv/lib/python3.10/site-packages/pandas/io/sql.py", line 2672, in execute
    cur = self.con.cursor()
AttributeError: 'Engine' object has no attribute 'cursor'
[2024-05-15T04:08:43.841+0800] {taskinstance.py:1206} INFO - Marking task as UP_FOR_RETRY. dag_id=census_data_pipeline, task_id=store_data, run_id=manual__2024-05-14T20:03:27.189773+00:00, execution_date=20240514T200327, start_date=20240514T200843, end_date=20240514T200843
[2024-05-15T04:08:43.851+0800] {standard_task_runner.py:110} ERROR - Failed to execute job 20 for task store_data ('Engine' object has no attribute 'cursor'; 114434)
[2024-05-15T04:08:43.869+0800] {local_task_job_runner.py:240} INFO - Task exited with return code 1
[2024-05-15T04:08:43.888+0800] {taskinstance.py:3498} INFO - 0 downstream tasks scheduled from follow-on schedule check
[2024-05-15T04:08:43.889+0800] {local_task_job_runner.py:222} INFO - ::endgroup::
